Workbook

Sheet __FDSCACHE__
B1: This sheet contains Factset binary data for use with this workbook's =FDS codes. Modifying the worksheet's contents may damage the workbook's =FDS functionality.

Sheet Cover Page
C11: Macabacus Initial Public Offering Model | L11: Strictly Confidential
C13: Table of Contents
C15: Assumptions
C16: Fully Diluted Shares Outstanding
C17: IPO Calculations
C20: © 2023 Macabacus, LLC
C22: DISCLAIMER
C23: This model represents a hypothetical DCF of a hypothetical company. Any similarity between the financial metrics of this company and actual companies
C24: is purely coincidental. Macabacus does not provide investment, accounting or tax advice. Additionally, tax and accounting rules used in the model are
C25: illustrative and may not reflect current tax or accounting rules and standards.
C27: DISCLAIMER
C28: Except as otherwise expressly stated, including but not limited to in a license or other agreement governing the use of specific content, all content in this
C29: model is provided "as is," and Macabacus makes no representations or warranties, express or implied, including but not limited to warranties
... C51: feedback@macabacus.com

Sheet Assumptions
B3: IPO Assumptions
B4: ($ and shares in millions, except per share amounts) | F4: Value
B6: Filing range – low | F6: 20
B7: Filing range – high | F7: 22
B9: Primary shares issued | F9: 5.5
B10: Secondary shares sold | F10: 4.5
B12: Underwriting discount (%) | F12: 0.06
B13: IPO discount (%) | F13: 0.15
B15: Overallotment
B16: Overallotment ("Greenshoe") (%) | F16: 0.15
B17: Primary allocation (%) | F17: 1
B18: Exercise shoe? | F18: 1
B20: IPO fees & expenses
B21: SEC registration fee | F21: 0.03483
B22: FINRA Filing fee | F22: 0.0305
B23: Nasdaq listing fees and expenses | F23: 0.025
B24: Transfer agent and registrar fees and expenses | F24: 0.1
B25: Printing fees and expenses | F25: 0.7
B26: Legal fees and expenses | F26: 3
B27: Accounting fees and expenses | F27: 1.5
B28: Miscellaneous | F28: 0.11
B32: Issuer Assumptions
B33: ($ and shares in millions, except per share amounts) | F33: Value
B35: Class A common stock | F35: 20.3
B36: Class B common stock | F36: 26.1
B38: Options strike price | F38: 20
B39: Options outstanding | F39: 2.9
B41: Issuer 2023E earnings | F41: 70
B42: Issuer 2024E earnings | F42: 95

Sheet FDSO
B3: Fully Diluted Share Count ("FDSO") Matrix
B5: Options strike price | D5: =Assumptions!F38 -> 20
B6: Options outstanding | D6: =Assumptions!F39 -> 2.9
E8: Potential Range of IPO Prices
A9: 1 | B9: (shares in millions) | E9: 18 | F9: =E9+1 -> 19 | G9: =F9+1 -> 20 | H9: =G9+1 -> 21 | I9: =H9+1 -> 22 | J9: =I9+1 -> 23 | K9: =J9+1 -> 24
A10: =A9+1 -> 2
A11: =A10+1 -> 3 | B11: =Assumptions!B35 -> Class A common stock | E11: =Assumptions!F35 -> 20.3 | F11: =E11 -> 20.3 | G11: =F11 -> 20.3 | H11: =G11 -> 20.3 | I11: =H11 -> 20.3 | J11: =I11 -> 20.3 | K11: =J11 -> 20.3
A12: =A11+1 -> 4 | B12: =Assumptions!B36 -> Class B common stock | E12: =Assumptions!F36 -> 26.1 | F12: =E12 -> 26.1 | G12: =F12 -> 26.1 | H12: =G12 -> 26.1 | I12: =H12 -> 26.1 | J12: =I12 -> 26.1 | K12: =J12 -> 26.1
A13: =A12+1 -> 5 | B13: Total basic shares outstanding | E13: =SUM(E11:E12) -> 46.4 | F13: =SUM(F11:F12) -> 46.4 | G13: =SUM(G11:G12) -> 46.4 | H13: =SUM(H11:H12) -> 46.4 | I13: =SUM(I11:I12) -> 46.4 | J13: =SUM(J11:J12) -> 46.4 | K13: =SUM(K11:K12) -> 46.4
A14: =A13+1 -> 6 | B14: ( + ) Stock options | E14: =IF($D$5<E9,$D$6-$D$6*$D$5/E9,0) -> 0 | F14: =IF($D$5<F9,$D$6-$D$6*$D$5/F9,0) -> 0 | G14: =IF($D$5<G9,$D$6-$D$6*$D$5/G9,0) -> 0 | H14: =IF($D$5<H9,$D$6-$D$6*$D$5/H9,0) -> 0.13809524 | I14: =IF($D$5<I9,$D$6-$D$6*$D$5/I9,0) -> 0.26363636 | J14: =IF($D$5<J9,$D$6-$D$6*$D$5/J9,0) -> 0.37826087 | K14: =IF($D$5<K9,$D$6-$D$6*$D$5/K9,0) -> 0.48333333
A15: =A14+1 -> 7 | B15: Fully diluted shares outstanding | E15: =SUM(E13:E14) -> 46.4 | F15: =SUM(F13:F14) -> 46.4 | G15: =SUM(G13:G14) -> 46.4 | H15: =SUM(H13:H14) -> 46.538095 | I15: =SUM(I13:I14) -> 46.663636 | J15: =SUM(J13:J14) -> 46.778261 | K15: =SUM(K13:K14) -> 46.883333

Sheet IPO
B3: IPO Calculations
F4: Filing Range
B5: ($ and shares in millions, except per share amounts) | F5: Low | G5: Midpoint | H5: High
B7: Offering price per share | F7: =Assumptions!F6 -> 20 | G7: =AVERAGE(F7,H7) -> 21 | H7: =Assumptions!F7 -> 22
B9: Shares
B11: Shares offered
B12: Primary shares issued | F12: =Assumptions!$F9 -> 5.5 | G12: =Assumptions!$F9 -> 5.5 | H12: =Assumptions!$F9 -> 5.5
B13: Secondary shares sold | F13: =Assumptions!$F10 -> 4.5 | G13: =Assumptions!$F10 -> 4.5 | H13: =Assumptions!$F10 -> 4.5
B14: Base deal shares issued/sold | F14: =SUM(F12:F13) -> 10 | G14: =SUM(G12:G13) -> 10 | H14: =SUM(H12:H13) -> 10
B15: Overallotment – primary shares | F15: =F14*Assumptions!$F$16*Assumptions!$F$17*Assumptions!$F$18 -> 1.5 | G15: =G14*Assumptions!$F$16*Assumptions!$F$17*Assumptions!$F$18 -> 1.5 | H15: =H14*Assumptions!$F$16*Assumptions!$F$17*Assumptions!$F$18 -> 1.5
B16: Overallotment – secondary shares | F16: =F14*Assumptions!$F$16*(1-Assumptions!$F$17)*Assumptions!$F$18 -> 0 | G16: =G14*Assumptions!$F$16*(1-Assumptions!$F$17)*Assumptions!$F$18 -> 0 | H16: =H14*Assumptions!$F$16*(1-Assumptions!$F$17)*Assumptions!$F$18 -> 0
B17: Total overallotment | F17: =SUM(F15:F16) -> 1.5 | G17: =SUM(G15:G16) -> 1.5 | H17: =SUM(H15:H16) -> 1.5
B18: Total shares issued/sold | F18: =F17+F14 -> 11.5 | G18: =G17+G14 -> 11.5 | H18: =H17+H14 -> 11.5
B20: Pro forma shares
B21: Existing Issuer FDSO | F21: =HLOOKUP(F$7,FDSO!$E$9:$K$15,FDSO!$A$15,FALSE) -> 46.4 | G21: =HLOOKUP(G$7,FDSO!$E$9:$K$15,FDSO!$A$15,FALSE) -> 46.538095 | H21: =HLOOKUP(H$7,FDSO!$E$9:$K$15,FDSO!$A$15,FALSE) -> 46.663636
B22: ( + ) Primary shares issued | F22: =F12+F15 -> 7 | G22: =G12+G15 -> 7 | H22: =H12+H15 -> 7
B23: Pro forma Issuer FDSO | F23: =SUM(F21:F22) -> 53.4 | G23: =SUM(G21:G22) -> 53.538095 | H23: =SUM(H21:H22) -> 53.663636
B25: Offering Size
B27: Base deal | F27: =F14*F7 -> 200 | G27: =G14*G7 -> 210 | H27: =H14*H7 -> 220
B28: ( + ) Overallotment | F28: =F17*F7 -> 30 | G28: =G17*G7 -> 31.5 | H28: =H17*H7 -> 33
B29: Total offering size | F29: =SUM(F27:F28) -> 230 | G29: =SUM(G27:G28) -> 241.5 | H29: =SUM(H27:H28) -> 253
B31: IPO Discount & Fees
B33: Underwriting discount
B34: IPO price per share | F34: =F7 -> 20 | G34: =G7 -> 21 | H34: =H7 -> 22
B35: ="( – ) Underwriting discount ("&TEXT(Assumptions!F12,"0.0%")&")" -> ( – ) Underwriting discount (6.0%) | F35: =-Assumptions!$F$12*F34 -> -1.2 | G35: =-Assumptions!$F$12*G34 -> -1.26 | H35: =-Assumptions!$F$12*H34 -> -1.32
B36: Net IPO price per share | F36: =SUM(F34:F35) -> 18.8 | G36: =SUM(G34:G35) -> 19.74 | H36: =SUM(H34:H35) -> 20.68
B38: Offering expenses
B39: =Assumptions!B21 -> SEC registration fee | F39: =Assumptions!F21 -> 0.03483 | G39: =F39 -> 0.03483 | H39: =G39 -> 0.03483
B40: =Assumptions!B22 -> FINRA Filing fee | F40: =Assumptions!F22 -> 0.0305 | G40: =F40 -> 0.0305 | H40: =G40 -> 0.0305
B41: =Assumptions!B23 -> Nasdaq listing fees and expenses | F41: =Assumptions!F23 -> 0.025 | G41: =F41 -> 0.025 | H41: =G41 -> 0.025
B42: =Assumptions!B24 -> Transfer agent and registrar fees and expenses | F42: =Assumptions!F24 -> 0.1 | G42: =F42 -> 0.1 | H42: =G42 -> 0.1
B43: =Assumptions!B25 -> Printing fees and expenses | F43: =Assumptions!F25 -> 0.7 | G43: =F43 -> 0.7 | H43: =G43 -> 0.7
B44: =Assumptions!B26 -> Legal fees and expenses | F44: =Assumptions!F26 -> 3 | G44: =F44 -> 3 | H44: =G44 -> 3
B45: =Assumptions!B27 -> Accounting fees and expenses | F45: =Assumptions!F27 -> 1.5 | G45: =F45 -> 1.5 | H45: =G45 -> 1.5
B46: =Assumptions!B28 -> Miscellaneous | F46: =Assumptions!F28 -> 0.11 | G46: =F46 -> 0.11 | H46: =G46 -> 0.11
B47: Total expenses | F47: =SUM(F39:F46) -> 5.50033 | G47: =SUM(G39:G46) -> 5.50033 | H47: =SUM(H39:H46) -> 5.50033
B49: IPO Proceeds
B51: Gross primary proceeds | F51: =F34*F22 -> 140 | G51: =G34*G22 -> 147 | H51: =H34*H22 -> 154
B52: ( – ) Underwriting discount | F52: =F35*F22 -> -8.4 | G52: =G35*G22 -> -8.82 | H52: =H35*H22 -> -9.24
B53: ( – ) Expenses | F53: =-F47 -> -5.50033 | G53: =-G47 -> -5.50033 | H53: =-H47 -> -5.50033
...
