Workbook

Sheet Calculator
A1: CLEAN ENERGY CREDIT UNION SOLAR PV SYSTEM "COMBO LOAN" PAYMENT CALCULATOR
A2: * Please note this is for estimating and illustrative purposes only, and may not exactly match the approved loan and payment amounts
A3: * Shaded cells require user input | D3: Revised: 01-Sep-2023
A5: Basic Info:
B6: Enter total contract price | C6: 20000
B7: Cash/Down payment(s) | C7: 0
B8: Amount financed | C8: =C6-C7 -> 20000 | D8: =IF(C8>90000,"ERROR: amount financed cannot exceed $90,000","Maximum amount for a short-term, long-term, or combo solar PV system loan is $90,000") -> Maximum amount for a short-term, long-term, or combo solar PV system loan is $90,000
A9: Long-Term Loan Info:
B10: Enter loan-to-value (LTV) up to max 80% | C10: 0.7 | D10: =IF(SUM($C$10,$C$17)>1,"ERROR: total LTV of both loans cannot exceed 100%",IF($C$10>80%,"ERROR: LTV must be < 80%","Must be <= 80%")) -> Must be <= 80%
B11: Loan amount | C11: =C10*C8 -> 14000 | D11: Maximum limit for a short-term, long-term, or "combo" solar PV system loan is $90,000
B12: Choose loan term (12, 15, or 20 years) | C12: 12 | D12: years
B13: Choose interest Rate | C13: =IF($C$12=12,8.75%,IF($C$12=15,9.25%,IF($C$12=20,9.5%,9.5%))) -> 0.0875 | D13: =IF($C$12=12,"For 12-year loans, use 8.75% as the default rate (NOTE: rates vary by FICO score)",IF(C$12=15,"For 15-year loans, use 9.25% as default rate (NOTE: rates vary by FICO score)",IF(C$12=20,"For 20-year loans, use 9.50% as default rate (NOTE: rates vary by FICO score)","ERROR"))) -> For 12-year loans, use 8.75% as the default rate (NOTE: rates vary by FICO score)
B14: Estimated Monthly Payment | C14: =IF($C$12=12,ROUNDUP(-PMT($C$13/12,144,$C$11,0,),0),IF($C$12=15,ROUNDUP(-PMT($C$13/12,180,$C$11,0,),0),IF($C$12=20,ROUNDUP(-PMT($C$13/12,240,$C$11,0,),0),"ERROR"))) -> 158 | D14: per month
B15: Payment Factor | C15: =1000*C14/C11 -> 11.285714 | D15: per $1,000 financed
A16: Short-Term Loan Info:
B17: Enter loan-to-value (LTV) up to max 100% | C17: 0.3 | D17: =IF(SUM($C$10,$C$17)>1,"ERROR: total LTV of both loans cannot exceed 100%","total LTV of both loans must be <= 100%") -> total LTV of both loans must be <= 100%
B18: Loan amount | C18: =C8*C17 -> 6000 | D18: =IF(C18>90000,"ERROR: amount financed cannot exceed $90,000","Maximum amount for a short-term, long-term, or combo solar PV system loan is $90,000") -> Maximum amount for a short-term, long-term, or combo solar PV system loan is $90,000
B19: Choose loan term (12 or 18 months) | C19: 12 | D19: months
B20: Choose promotional Interest Rate (if loan is fully repaid on or before maturity date) | C20: 0.0775 | D20: Use 7.75% as default rate (NOTE: rates vary by FICO score)
B21: Actual Interest Rate | C21: 0.1799
B22: Promotional Estimated Balloon Payment (if loan is fully repaid by maturity date) | C22: =ROUNDUP(C18*(1+C20/12)^C19,2) -> 6481.88 | D22: due by maturity date
B23: Estimated Balloon Payment (if loan is not fully repaid by maturity date) | C23: =ROUNDUP(C18*(1+C21/12)^C19,2) -> 7173.01 | D23: due upon maturity date at end of loan term if loan is not paid by maturity date
B30: long-term loan term | C30: 12
C31: 15
C32: 20
B34: short-term loan term | C34: 12
C35: 18

Sheet LT loan amortization table
C2: 12-Year Loan Amortization Table | J2: 15-Year Loan Amortization Table | Q2: 20-Year Loan Amortization Table
A4: Month | B4: Estimated Monthly Payment | C4: Beginning Balance | D4: Principal | E4: Interest | F4: Ending Balance | H4: Month | I4: Estimated Monthly Payment | J4: Beginning Balance | K4: Principal | L4: Interest | M4: Ending Balance | O4: Month | P4: Estimated Monthly Payment | Q4: Beginning Balance | R4: Principal | S4: Interest | T4: Ending Balance
A5: 1 | B5: =IF(Calculator!$C$12=12,Calculator!$C$14,"") -> 158 | C5: =IF(Calculator!$C$12=12,Calculator!$C$11,"") -> 14000 | D5: =IF(Calculator!$C$12=12,ROUNDUP(-PPMT(Calculator!$C$13/12,$A5,144,Calculator!$C$11,0,),0),"") -> 56 | E5: =IF(Calculator!$C$12=12,ROUNDUP(-IPMT(Calculator!$C$13/12,$A5,144,Calculator!$C$11,0,),0),"") -> 103 | F5: =IF(Calculator!$C$12=12,C5-D5,"") -> 13944 | H5: 1 | I5: =IF(Calculator!$C$12=15,Calculator!$C$14,"") | J5: =IF(Calculator!$C$12=15,Calculator!$C$11,"") | K5: =IF(Calculator!$C$12=15,ROUNDUP(-PPMT(Calculator!$C$13/12,$H5,180,Calculator!$C$11,0,),0),"") | L5: =IF(Calculator!$C$12=15,ROUNDUP(-IPMT(Calculator!$C$13/12,$H5,180,Calculator!$C$11,0,),0),"") | M5: =IF(Calculator!$C$12=15,J5-K5,"") | O5: 1 | P5: =IF(Calculator!$C$12=20,Calculator!$C$14,"") | Q5: =IF(Calculator!$C$12=20,Calculator!$C$11,"") | R5: =IF(Calculator!$C$12=20,ROUNDUP(-PPMT(Calculator!$C$13/12,$O5,240,Calculator!$C$11,0,),0),"") | S5: =IF(Calculator!$C$12=20,ROUNDUP(-IPMT(Calculator!$C$13/12,$O5,240,Calculator!$C$11,0,),0),"") | T5: =IF(Calculator!$C$12=20,Q5-R5,"")
A6: 2 | B6: =IF(Calculator!$C$12=12,Calculator!$C$14,"") -> 158 | C6: =F5 -> 13944 | D6: =IF(Calculator!$C$12=12,ROUNDUP(-PPMT(Calculator!$C$13/12,$A6,144,Calculator!$C$11,0,),0),"") -> 56 | E6: =IF(Calculator!$C$12=12,ROUNDUP(-IPMT(Calculator!$C$13/12,$A6,144,Calculator!$C$11,0,),0),"") -> 102 | F6: =IF(Calculator!$C$12=12,C6-D6,"") -> 13888 | H6: 2 | I6: =IF(Calculator!$C$12=12,"",Calculator!$C$14) | J6: =M5 | K6: =IF(Calculator!$C$12=15,ROUNDUP(-PPMT(Calculator!$C$13/12,$H6,180,Calculator!$C$11,0,),0),"") | L6: =IF(Calculator!$C$12=15,ROUNDUP(-IPMT(Calculator!$C$13/12,$H6,180,Calculator!$C$11,0,),0),"") | M6: =IF(Calculator!$C$12=15,J6-K6,"") | O6: 2 | P6: =IF(Calculator!$C$12=20,Calculator!$C$14,"") | Q6: =T5 | R6: =IF(Calculator!$C$12=20,ROUNDUP(-PPMT(Calculator!$C$13/12,$O6,240,Calculator!$C$11,0,),0),"") | S6: =IF(Calculator!$C$12=20,ROUNDUP(-IPMT(Calculator!$C$13/12,$O6,240,Calculator!$C$11,0,),0),"") | T6: =IF(Calculator!$C$12=20,Q6-R6,"")
A7: 3 | B7: =IF(Calculator!$C$12=12,Calculator!$C$14,"") -> 158 | C7: =F6 -> 13888 | D7: =IF(Calculator!$C$12=12,ROUNDUP(-PPMT(Calculator!$C$13/12,$A7,144,Calculator!$C$11,0,),0),"") -> 57 | E7: =IF(Calculator!$C$12=12,ROUNDUP(-IPMT(Calculator!$C$13/12,$A7,144,Calculator!$C$11,0,),0),"") -> 102 | F7: =IF(Calculator!$C$12=12,C7-D7,"") -> 13831 | H7: 3 | I7: =IF(Calculator!$C$12=12,"",Calculator!$C$14) | J7: =M6 | K7: =IF(Calculator!$C$12=15,ROUNDUP(-PPMT(Calculator!$C$13/12,$H7,180,Calculator!$C$11,0,),0),"") | L7: =IF(Calculator!$C$12=15,ROUNDUP(-IPMT(Calculator!$C$13/12,$H7,180,Calculator!$C$11,0,),0),"") | M7: =IF(Calculator!$C$12=15,J7-K7,"") | O7: 3 | P7: =IF(Calculator!$C$12=20,Calculator!$C$14,"") | Q7: =T6 | R7: =IF(Calculator!$C$12=20,ROUNDUP(-PPMT(Calculator!$C$13/12,$O7,240,Calculator!$C$11,0,),0),"") | S7: =IF(Calculator!$C$12=20,ROUNDUP(-IPMT(Calculator!$C$13/12,$O7,240,Calculator!$C$11,0,),0),"") | T7: =IF(Calculator!$C$12=20,Q7-R7,"")
A8: 4 | B8: =IF(Calculator!$C$12=12,Calculator!$C$14,"") -> 158 | C8: =F7 -> 13831 | D8: =IF(Calculator!$C$12=12,ROUNDUP(-PPMT(Calculator!$C$13/12,$A8,144,Calculator!$C$11,0,),0),"") -> 57 | E8: =IF(Calculator!$C$12=12,ROUNDUP(-IPMT(Calculator!$C$13/12,$A8,144,Calculator!$C$11,0,),0),"") -> 101 | F8: =IF(Calculator!$C$12=12,C8-D8,"") -> 13774 | H8: 4 | I8: =IF(Calculator!$C$12=12,"",Calculator!$C$14) | J8: =M7 | K8: =IF(Calculator!$C$12=15,ROUNDUP(-PPMT(Calculator!$C$13/12,$H8,180,Calculator!$C$11,0,),0),"") | L8: =IF(Calculator!$C$12=15,ROUNDUP(-IPMT(Calculator!$C$13/12,$H8,180,Calculator!$C$11,0,),0),"") | M8: =IF(Calculator!$C$12=15,J8-K8,"") | O8: 4 | P8: =IF(Calculator!$C$12=20,Calculator!$C$14,"") | Q8: =T7 | R8: =IF(Calculator!$C$12=20,ROUNDUP(-PPMT(Calculator!$C$13/12,$O8,240,Calculator!$C$11,0,),0),"") | S8: =IF(Calculator!$C$12=20,ROUNDUP(-IPMT(Calculator!$C$13/12,$O8,240,Calculator!$C$11,0,),0),"") | T8: =IF(Calculator!$C$12=20,Q8-R8,"")
A9: 5 | B9: =IF(Calculator!$C$12=12,Calculator!$C$14,"") -> 158 | C9: =F8 -> 13774 | D9: =IF(Calculator!$C$12=12,ROUNDUP(-PPMT(Calculator!$C$13/12,$A9,144,Calculator!$C$11,0,),0),"") -> 57 | E9: =IF(Calculator!$C$12=12,ROUNDUP(-IPMT(Calculator!$C$13/12,$A9,144,Calculator!$C$11,0,),0),"") -> 101 | F9: =IF(Calculator!$C$12=12,C9-D9,"") -> 13717 | H9: 5 | I9: =IF(Calculator!$C$12=12,"",Calculator!$C$14) | J9: =M8 | K9: =IF(Calculator!$C$12=15,ROUNDUP(-PPMT(Calculator!$C$13/12,$H9,180,Calculator!$C$11,0,),0),"") | L9: =IF(Calculator!$C$12=15,ROUNDUP(-IPMT(Calculator!$C$13/12,$H9,180,Calculator!$C$11,0,),0),"") | M9: =IF(Calculator!$C$12=15,J9-K9,"") | O9: 5 | P9: =IF(Calculator!$C$12=20,Calculator!$C$14,"") | Q9: =T8 | R9: =IF(Calculator!$C$12=20,ROUNDUP(-PPMT(Calculator!$C$13/12,$O9,240,Calculator!$C$11,0,),0),"") | S9: =IF(Calculator!$C$12=20,ROUNDUP(-IPMT(Calculator!$C$13/12,$O9,240,Calculator!$C$11,0,),0),"") | T9: =IF(Calculator!$C$12=20,Q9-R9,"")
A10: 6 | B10: =IF(Calculator!$C$12=12,Calculator!$C$14,"") -> 158 | C10: =F9 -> 13717 | D10: =IF(Calculator!$C$12=12,ROUNDUP(-PPMT(Calculator!$C$13/12,$A10,144,Calculator!$C$11,0,),0),"") -> 58 | E10: =IF(Calculator!$C$12=12,ROUNDUP(-IPMT(Calculator!$C$13/12,$A10,144,Calculator!$C$11,0,),0),"") -> 101 | F10: =IF(Calculator!$C$12=12,C10-D10,"") -> 13659 | H10: 6 | I10: =IF(Calculator!$C$12=12,"",Calculator!$C$14) | J10: =M9 | K10: =IF(Calculator!$C$12=15,ROUNDUP(-PPMT(Calculator!$C$13/12,$H10,180,Calculator!$C$11,0,),0),"") | L10: =IF(Calculator!$C$12=15,ROUNDUP(-IPMT(Calculator!$C$13/12,$H10,180,Calculator!$C$11,0,),0),"") | M10: =IF(Calculator!$C$12=15,J10-K10,"") | O10: 6 | P10: =IF(Calculator!$C$12=20,Calculator!$C$14,"") | Q10: =T9 | R10: =IF(Calculator!$C$12=20,ROUNDUP(-PPMT(Calculator!$C$13/12,$O10,240,Calculator!$C$11,0,),0),"") | S10: =IF(Calculator!$C$12=20,ROUNDUP(-IPMT(Calculator!$C$13/12,$O10,240,Calculator!$C$11,0,),0),"") | T10: =IF(Calculator!$C$12=20,Q10-R10,"")
A11: 7 | B11: =IF(Calculator!$C$12=12,Calculator!$C$14,"") -> 158 | C11: =F10 -> 13659 | D11: =IF(Calculator!$C$12=12,ROUNDUP(-PPMT(Calculator!$C$13/12,$A11,144,Calculator!$C$11,0,),0),"") -> 58 | E11: =IF(Calculator!$C$12=12,ROUNDUP(-IPMT(Calculator!$C$13/12,$A11,144,Calculator!$C$11,0,),0),"") -> 100 | F11: =IF(Calculator!$C$12=12,C11-D11,"") -> 13601 | H11: 7 | I11: =IF(Calculator!$C$12=12,"",Calculator!$C$14) | J11: =M10 | K11: =IF(Calculator!$C$12=15,ROUNDUP(-PPMT(Calculator!$C$13/12,$H11,180,Calculator!$C$11,0,),0),"") | L11: =IF(Calculator!$C$12=15,ROUNDUP(-IPMT(Calculator!$C$13/12,$H11,180,Calculator!$C$11,0,),0),"") | M11: =IF(Calculator!$C$12=15,J11-K11,"") | O11: 7 | P11: =IF(Calculator!$C$12=20,Calculator!$C$14,"") | Q11: =T10 | R11: =IF(Calculator!$C$12=20,ROUNDUP(-PPMT(Calculator!$C$13/12,$O11,240,Calculator!$C$11,0,),0),"") | S11: =IF(Calculator!$C$12=20,ROUNDUP(-IPMT(Calculator!$C$13/12,$O11,240,Calculator!$C$11,0,),0),"") | T11: =IF(Calculator!$C$12=20,Q11-R11,"")
A12: 8 | B12: =IF(Calculator!$C$12=12,Calculator!$C$14,"") -> 158 | C12: =F11 -> 13601 | D12: =IF(Calculator!$C$12=12,ROUNDUP(-PPMT(Calculator!$C$13/12,$A12,144,Calculator!$C$11,0,),0),"") -> 59 | E12: =IF(Calculator!$C$12=12,ROUNDUP(-IPMT(Calculator!$C$13/12,$A12,144,Calculator!$C$11,0,),0),"") -> 100 | F12: =IF(Calculator!$C$12=12,C12-D12,"") -> 13542 | H12: 8 | I12: =IF(Calculator!$C$12=12,"",Calculator!$C$14) | J12: =M11 | K12: =IF(Calculator!$C$12=15,ROUNDUP(-PPMT(Calculator!$C$13/12,$H12,180,Calculator!$C$11,0,),0),"") | L12: =IF(Calculator!$C$12=15,ROUNDUP(-IPMT(Calculator!$C$13/12,$H12,180,Calculator!$C$11,0,),0),"") | M12: =IF(Calculator!$C$12=15,J12-K12,"") | O12: 8 | P12: =IF(Calculator!$C$12=20,Calculator!$C$14,"") | Q12: =T11 | R12: =IF(Calculator!$C$12=20,ROUNDUP(-PPMT(Calculator!$C$13/12,$O12,240,Calculator!$C$11,0,),0),"") | S12: =IF(Calculator!$C$12=20,ROUNDUP(-IPMT(Calculator!$C$13/12,$O12,240,Calculator!$C$11,0,),0),"") | T12: =IF(Calculator!$C$12=20,Q12-R12,"")
A13: 9 | B13: =IF(Calculator!$C$12=12,Calculator!$C$14,"") -> 158 | C13: =F12 -> 13542 | D13: =IF(Calculator!$C$12=12,ROUNDUP(-PPMT(Calculator!$C$13/12,$A13,144,Calculator!$C$11,0,),0),"") -> 59 | E13: =IF(Calculator!$C$12=12,ROUNDUP(-IPMT(Calculator!$C$13/12,$A13,144,Calculator!$C$11,0,),0),"") -> 99 | F13: =IF(Calculator!$C$12=12,C13-D13,"") -> 13483 | H13: 9 | I13: =IF(Calculator!$C$12=12,"",Calculator!$C$14) | J13: =M12 | K13: =IF(Calculator!$C$12=15,ROUNDUP(-PPMT(Calculator!$C$13/12,$H13,180,Calculator!$C$11,0,),0),"") | L13: =IF(Calculator!$C$12=15,ROUNDUP(-IPMT(Calculator!$C$13/12,$H13,180,Calculator!$C$11,0,),0),"") | M13: =IF(Calculator!$C$12=15,J13-K13,"") | O13: 9 | P13: =IF(Calculator!$C$12=20,Calculator!$C$14,"") | Q13: =T12 | R13: =IF(Calculator!$C$12=20,ROUNDUP(-PPMT(Calculator!$C$13/12,$O13,240,Calculator!$C$11,0,),0),"") | S13: =IF(Calculator!$C$12=20,ROUNDUP(-IPMT(Calculator!$C$13/12,$O13,240,Calculator!$C$11,0,),0),"") | T13: =IF(Calculator!$C$12=20,Q13-R13,"")
A14: 10 | B14: =IF(Calculator!$C$12=12,Calculator!$C$14,"") -> 158 | C14: =F13 -> 13483 | D14: =IF(Calculator!$C$12=12,ROUNDUP(-PPMT(Calculator!$C$13/12,$A14,144,Calculator!$C$11,0,),0),"") -> 60 | E14: =IF(Calculator!$C$12=12,ROUNDUP(-IPMT(Calculator!$C$13/12,$A14,144,Calculator!$C$11,0,),0),"") -> 99 | F14: =IF(Calculator!$C$12=12,C14-D14,"") -> 13423 | H14: 10 | I14: =IF(Calculator!$C$12=12,"",Calculator!$C$14) | J14: =M13 | K14: =IF(Calculator!$C$12=15,ROUNDUP(-PPMT(Calculator!$C$13/12,$H14,180,Calculator!$C$11,0,),0),"") | L14: =IF(Calculator!$C$12=15,ROUNDUP(-IPMT(Calculator!$C$13/12,$H14,180,Calculator!$C$11,0,),0),"") | M14: =IF(Calculator!$C$12=15,J14-K14,"") | O14: 10 | P14: =IF(Calculator!$C$12=20,Calculator!$C$14,"") | Q14: =T13 | R14: =IF(Calculator!$C$12=20,ROUNDUP(-PPMT(Calculator!$C$13/12,$O14,240,Calculator!$C$11,0,),0),"") | S14: =IF(Calculator!$C$12=20,ROUNDUP(-IPMT(Calculator!$C$13/12,$O14,240,Calculator!$C$11,0,),0),"") | T14: =IF(Calculator!$C$12=20,Q14-R14,"")
A15: 11 | B15: =IF(Calculator!$C$12=12,Calculator!$C$14,"") -> 158 | C15: =F14 -> 13423 | D15: =IF(Calculator!$C$12=12,ROUNDUP(-PPMT(Calculator!$C$13/12,$A15,144,Calculator!$C$11,0,),0),"") -> 60 | E15: =IF(Calculator!$C$12=12,ROUNDUP(-IPMT(Calculator!$C$13/12,$A15,144,Calculator!$C$11,0,),0),"") -> 98 | F15: =IF(Calculator!$C$12=12,C15-D15,"") -> 13363 | H15: 11 | I15: =IF(Calculator!$C$12=12,"",Calculator!$C$14) | J15: =M14 | K15: =IF(Calculator!$C$12=15,ROUNDUP(-PPMT(Calculator!$C$13/12,$H15,180,Calculator!$C$11,0,),0),"") | L15: =IF(Calculator!$C$12=15,ROUNDUP(-IPMT(Calculator!$C$13/12,$H15,180,Calculator!$C$11,0,),0),"") | M15: =IF(Calculator!$C$12=15,J15-K15,"") | O15: 11 | P15: =IF(Calculator!$C$12=20,Calculator!$C$14,"") | Q15: =T14 | R15: =IF(Calculator!$C$12=20,ROUNDUP(-PPMT(Calculator!$C$13/12,$O15,240,Calculator!$C$11,0,),0),"") | S15: =IF(Calculator!$C$12=20,ROUNDUP(-IPMT(Calculator!$C$13/12,$O15,240,Calculator!$C$11,0,),0),"") | T15: =IF(Calculator!$C$12=20,Q15-R15,"")
A16: 12 | B16: =IF(Calculator!$C$12=12,Calculator!$C$14,"") -> 158 | C16: =F15 -> 13363 | D16: =IF(Calculator!$C$12=12,ROUNDUP(-PPMT(Calculator!$C$13/12,$A16,144,Calculator!$C$11,0,),0),"") -> 60 | E16: =IF(Calculator!$C$12=12,ROUNDUP(-IPMT(Calculator!$C$13/12,$A16,144,Calculator!$C$11,0,),0),"") -> 98 | F16: =IF(Calculator!$C$12=12,C16-D16,"") -> 13303 | H16: 12 | I16: =IF(Calculator!$C$12=12,"",Calculator!$C$14) | J16: =M15 | K16: =IF(Calculator!$C$12=15,ROUNDUP(-PPMT(Calculator!$C$13/12,$H16,180,Calculator!$C$11,0,),0),"") | L16: =IF(Calculator!$C$12=15,ROUNDUP(-IPMT(Calculator!$C$13/12,$H16,180,Calculator!$C$11,0,),0),"") | M16: =IF(Calculator!$C$12=15,J16-K16,"") | O16: 12 | P16: =IF(Calculator!$C$12=20,Calculator!$C$14,"") | Q16: =T15 | R16: =IF(Calculator!$C$12=20,ROUNDUP(-PPMT(Calculator!$C$13/12,$O16,240,Calculator!$C$11,0,),0),"") | S16: =IF(Calculator!$C$12=20,ROUNDUP(-IPMT(Calculator!$C$13/12,$O16,240,Calculator!$C$11,0,),0),"") | T16: =IF(Calculator!$C$12=20,Q16-R16,"")
A17: 13 | B17: =IF(Calculator!$C$12=12,Calculator!$C$14,"") -> 158 | C17: =F16 -> 13303 | D17: =IF(Calculator!$C$12=12,ROUNDUP(-PPMT(Calculator!$C$13/12,$A17,144,Calculator!$C$11,0,),0),"") -> 61 | E17: =IF(Calculator!$C$12=12,ROUNDUP(-IPMT(Calculator!$C$13/12,$A17,144,Calculator!$C$11,0,),0),"") -> 98 | F17: =IF(Calculator!$C$12=12,C17-D17,"") -> 13242 | H17: 13 | I17: =IF(Calculator!$C$12=12,"",Calculator!$C$14) | J17: =M16 | K17: =IF(Calculator!$C$12=15,ROUNDUP(-PPMT(Calculator!$C$13/12,$H17,180,Calculator!$C$11,0,),0),"") | L17: =IF(Calculator!$C$12=15,ROUNDUP(-IPMT(Calculator!$C$13/12,$H17,180,Calculator!$C$11,0,),0),"") | M17: =IF(Calculator!$C$12=15,J17-K17,"") | O17: 13 | P17: =IF(Calculator!$C$12=20,Calculator!$C$14,"") | Q17: =T16 | R17: =IF(Calculator!$C$12=20,ROUNDUP(-PPMT(Calculator!$C$13/12,$O17,240,Calculator!$C$11,0,),0),"") | S17: =IF(Calculator!$C$12=20,ROUNDUP(-IPMT(Calculator!$C$13/12,$O17,240,Calculator!$C$11,0,),0),"") | T17: =IF(Calculator!$C$12=20,Q17-R17,"")
... A147: 143 | B147: =IF(Calculator!$C$12=12,Calculator!$C$14,"") -> 158 | C147: =F146 -> 236 | D147: =IF(Calculator!$C$12=12,ROUNDUP(-PPMT(Calculator!$C$13/12,$A147,144,Calculator!$C$11,0,),0),"") -> 156 | E147: =IF(Calculator!$C$12=12,ROUNDUP(-IPMT(Calculator!$C$13/12,$A147,144,Calculator!$C$11,0,),0),"") -> 3 | F147: =IF(Calculator!$C$12=12,C147-D147,"") -> 80 | H147: 143 | I147: =IF(Calculator!$C$12=12,"",Calculator!$C$14) | J147: =M146 | K147: =IF(Calculator!$C$12=15,ROUNDUP(-PPMT(Calculator!$C$13/12,$H147,180,Calculator!$C$11,0,),0),"") | L147: =IF(Calculator!$C$12=15,ROUNDUP(-IPMT(Calculator!$C$13/12,$H147,180,Calculator!$C$11,0,),0),"") | M147: =IF(Calculator!$C$12=15,J147-K147,"") | O147: 143 | P147: =IF(Calculator!$C$12=20,Calculator!$C$14,"") | Q147: =T146 | R147: =IF(Calculator!$C$12=20,ROUNDUP(-PPMT(Calculator!$C$13/12,$O147,240,Calculator!$C$11,0,),0),"") | S147: =IF(Calculator!$C$12=20,ROUNDUP(-IPMT(Calculator!$C$13/12,$O147,240,Calculator!$C$11,0,),0),"") | T147: =IF(Calculator!$C$12=20,Q147-R147,"")
A148: 144 | B148: =D148+E148 -> 80.583333 | C148: =F147 -> 80 | D148: =C148 -> 80 | E148: =F147*Calculator!$C$13/12 -> 0.58333333 | F148: =IF(Calculator!$C$12=12,C148-D148,"") -> 0 | H148: 144 | I148: =IF(Calculator!$C$12=12,"",Calculator!$C$14) | J148: =M147 | K148: =IF(Calculator!$C$12=15,ROUNDUP(-PPMT(Calculator!$C$13/12,$H148,180,Calculator!$C$11,0,),0),"") | L148: =IF(Calculator!$C$12=15,ROUNDUP(-IPMT(Calculator!$C$13/12,$H148,180,Calculator!$C$11,0,),0),"") | M148: =IF(Calculator!$C$12=15,J148-K148,"") | O148: 144 | P148: =IF(Calculator!$C$12=20,Calculator!$C$14,"") | Q148: =T147 | R148: =IF(Calculator!$C$12=20,ROUNDUP(-PPMT(Calculator!$C$13/12,$O148,240,Calculator!$C$11,0,),0),"") | S148: =IF(Calculator!$C$12=20,ROUNDUP(-IPMT(Calculator!$C$13/12,$O148,240,Calculator!$C$11,0,),0),"") | T148: =IF(Calculator!$C$12=20,Q148-R148,"")
H149: 145 | I149: =IF(Calculator!$C$12=12,"",Calculator!$C$14) | J149: =M148 | K149: =IF(Calculator!$C$12=15,ROUNDUP(-PPMT(Calculator!$C$13/12,$H149,180,Calculator!$C$11,0,),0),"") | L149: =IF(Calculator!$C$12=15,ROUNDUP(-IPMT(Calculator!$C$13/12,$H149,180,Calculator!$C$11,0,),0),"") | M149: =IF(Calculator!$C$12=15,J149-K149,"") | O149: 145 | P149: =IF(Calculator!$C$12=20,Calculator!$C$14,"") | Q149: =T148 | R149: =IF(Calculator!$C$12=20,ROUNDUP(-PPMT(Calculator!$C$13/12,$O149,240,Calculator!$C$11,0,),0),"") | S149: =IF(Calculator!$C$12=20,ROUNDUP(-IPMT(Calculator!$C$13/12,$O149,240,Calculator!$C$11,0,),0),"") | T149: =IF(Calculator!$C$12=20,Q149-R149,"")
H150: 146 | I150: =IF(Calculator!$C$12=12,"",Calculator!$C$14) | J150: =M149 | K150: =IF(Calculator!$C$12=15,ROUNDUP(-PPMT(Calculator!$C$13/12,$H150,180,Calculator!$C$11,0,),0),"") | L150: =IF(Calculator!$C$12=15,ROUNDUP(-IPMT(Calculator!$C$13/12,$H150,180,Calculator!$C$11,0,),0),"") | M150: =IF(Calculator!$C$12=15,J150-K150,"") | O150: 146 | P150: =IF(Calculator!$C$12=20,Calculator!$C$14,"") | Q150: =T149 | R150: =IF(Calculator!$C$12=20,ROUNDUP(-PPMT(Calculator!$C$13/12,$O150,240,Calculator!$C$11,0,),0),"") | S150: =IF(Calculator!$C$12=20,ROUNDUP(-IPMT(Calculator!$C$13/12,$O150,240,Calculator!$C$11,0,),0),"") | T150: =IF(Calculator!$C$12=20,Q150-R150,"")
H151: 147 | I151: =IF(Calculator!$C$12=12,"",Calculator!$C$14) | J151: =M150 | K151: =IF(Calculator!$C$12=15,ROUNDUP(-PPMT(Calculator!$C$13/12,$H151,180,Calculator!$C$11,0,),0),"") | L151: =IF(Calculator!$C$12=15,ROUNDUP(-IPMT(Calculator!$C$13/12,$H151,180,Calculator!$C$11,0,),0),"") | M151: =IF(Calculator!$C$12=15,J151-K151,"") | O151: 147 | P151: =IF(Calculator!$C$12=20,Calculator!$C$14,"") | Q151: =T150 | R151: =IF(Calculator!$C$12=20,ROUNDUP(-PPMT(Calculator!$C$13/12,$O151,240,Calculator!$C$11,0,),0),"") | S151: =IF(Calculator!$C$12=20,ROUNDUP(-IPMT(Calculator!$C$13/12,$O151,240,Calculator!$C$11,0,),0),"") | T151: =IF(Calculator!$C$12=20,Q151-R151,"")
H152: 148 | I152: =IF(Calculator!$C$12=12,"",Calculator!$C$14) | J152: =M151 | K152: =IF(Calculator!$C$12=15,ROUNDUP(-PPMT(Calculator!$C$13/12,$H152,180,Calculator!$C$11,0,),0),"") | L152: =IF(Calculator!$C$12=15,ROUNDUP(-IPMT(Calculator!$C$13/12,$H152,180,Calculator!$C$11,0,),0),"") | M152: =IF(Calculator!$C$12=15,J152-K152,"") | O152: 148 | P152: =IF(Calculator!$C$12=20,Calculator!$C$14,"") | Q152: =T151 | R152: =IF(Calculator!$C$12=20,ROUNDUP(-PPMT(Calculator!$C$13/12,$O152,240,Calculator!$C$11,0,),0),"") | S152: =IF(Calculator!$C$12=20,ROUNDUP(-IPMT(Calculator!$C$13/12,$O152,240,Calculator!$C$11,0,),0),"") | T152: =IF(Calculator!$C$12=20,Q152-R152,"")
H153: 149 | I153: =IF(Calculator!$C$12=12,"",Calculator!$C$14) | J153: =M152 | K153: =IF(Calculator!$C$12=15,ROUNDUP(-PPMT(Calculator!$C$13/12,$H153,180,Calculator!$C$11,0,),0),"") | L153: =IF(Calculator!$C$12=15,ROUNDUP(-IPMT(Calculator!$C$13/12,$H153,180,Calculator!$C$11,0,),0),"") | M153: =IF(Calculator!$C$12=15,J153-K153,"") | O153: 149 | P153: =IF(Calculator!$C$12=20,Calculator!$C$14,"") | Q153: =T152 | R153: =IF(Calculator!$C$12=20,ROUNDUP(-PPMT(Calculator!$C$13/12,$O153,240,Calculator!$C$11,0,),0),"") | S153: =IF(Calculator!$C$12=20,ROUNDUP(-IPMT(Calculator!$C$13/12,$O153,240,Calculator!$C$11,0,),0),"") | T153: =IF(Calculator!$C$12=20,Q153-R153,"")
H154: 150 | I154: =IF(Calculator!$C$12=12,"",Calculator!$C$14) | J154: =M153 | K154: =IF(Calculator!$C$12=15,ROUNDUP(-PPMT(Calculator!$C$13/12,$H154,180,Calculator!$C$11,0,),0),"") | L154: =IF(Calculator!$C$12=15,ROUNDUP(-IPMT(Calculator!$C$13/12,$H154,180,Calculator!$C$11,0,),0),"") | M154: =IF(Calculator!$C$12=15,J154-K154,"") | O154: 150 | P154: =IF(Calculator!$C$12=20,Calculator!$C$14,"") | Q154: =T153 | R154: =IF(Calculator!$C$12=20,ROUNDUP(-PPMT(Calculator!$C$13/12,$O154,240,Calculator!$C$11,0,),0),"") | S154: =IF(Calculator!$C$12=20,ROUNDUP(-IPMT(Calculator!$C$13/12,$O154,240,Calculator!$C$11,0,),0),"") | T154: =IF(Calculator!$C$12=20,Q154-R154,"")
H155: 151 | I155: =IF(Calculator!$C$12=12,"",Calculator!$C$14) | J155: =M154 | K155: =IF(Calculator!$C$12=15,ROUNDUP(-PPMT(Calculator!$C$13/12,$H155,180,Calculator!$C$11,0,),0),"") | L155: =IF(Calculator!$C$12=15,ROUNDUP(-IPMT(Calculator!$C$13/12,$H155,180,Calculator!$C$11,0,),0),"") | M155: =IF(Calculator!$C$12=15,J155-K155,"") | O155: 151 | P155: =IF(Calculator!$C$12=20,Calculator!$C$14,"") | Q155: =T154 | R155: =IF(Calculator!$C$12=20,ROUNDUP(-PPMT(Calculator!$C$13/12,$O155,240,Calculator!$C$11,0,),0),"") | S155: =IF(Calculator!$C$12=20,ROUNDUP(-IPMT(Calculator!$C$13/12,$O155,240,Calculator!$C$11,0,),0),"") | T155: =IF(Calculator!$C$12=20,Q155-R155,"")
H156: 152 | I156: =IF(Calculator!$C$12=12,"",Calculator!$C$14) | J156: =M155 | K156: =IF(Calculator!$C$12=15,ROUNDUP(-PPMT(Calculator!$C$13/12,$H156,180,Calculator!$C$11,0,),0),"") | L156: =IF(Calculator!$C$12=15,ROUNDUP(-IPMT(Calculator!$C$13/12,$H156,180,Calculator!$C$11,0,),0),"") | M156: =IF(Calculator!$C$12=15,J156-K156,"") | O156: 152 | P156: =IF(Calculator!$C$12=20,Calculator!$C$14,"") | Q156: =T155 | R156: =IF(Calculator!$C$12=20,ROUNDUP(-PPMT(Calculator!$C$13/12,$O156,240,Calculator!$C$11,0,),0),"") | S156: =IF(Calculator!$C$12=20,ROUNDUP(-IPMT(Calculator!$C$13/12,$O156,240,Calculator!$C$11,0,),0),"") | T156: =IF(Calculator!$C$12=20,Q156-R156,"")
H157: 153 | I157: =IF(Calculator!$C$12=12,"",Calculator!$C$14) | J157: =M156 | K157: =IF(Calculator!$C$12=15,ROUNDUP(-PPMT(Calculator!$C$13/12,$H157,180,Calculator!$C$11,0,),0),"") | L157: =IF(Calculator!$C$12=15,ROUNDUP(-IPMT(Calculator!$C$13/12,$H157,180,Calculator!$C$11,0,),0),"") | M157: =IF(Calculator!$C$12=15,J157-K157,"") | O157: 153 | P157: =IF(Calculator!$C$12=20,Calculator!$C$14,"") | Q157: =T156 | R157: =IF(Calculator!$C$12=20,ROUNDUP(-PPMT(Calculator!$C$13/12,$O157,240,Calculator!$C$11,0,),0),"") | S157: =IF(Calculator!$C$12=20,ROUNDUP(-IPMT(Calculator!$C$13/12,$O157,240,Calculator!$C$11,0,),0),"") | T157: =IF(Calculator!$C$12=20,Q157-R157,"")
H158: 154 | I158: =IF(Calculator!$C$12=12,"",Calculator!$C$14) | J158: =M157 | K158: =IF(Calculator!$C$12=15,ROUNDUP(-PPMT(Calculator!$C$13/12,$H158,180,Calculator!$C$11,0,),0),"") | L158: =IF(Calculator!$C$12=15,ROUNDUP(-IPMT(Calculator!$C$13/12,$H158,180,Calculator!$C$11,0,),0),"") | M158: =IF(Calculator!$C$12=15,J158-K158,"") | O158: 154 | P158: =IF(Calculator!$C$12=20,Calculator!$C$14,"") | Q158: =T157 | R158: =IF(Calculator!$C$12=20,ROUNDUP(-PPMT(Calculator!$C$13/12,$O158,240,Calculator!$C$11,0,),0),"") | S158: =IF(Calculator!$C$12=20,ROUNDUP(-IPMT(Calculator!$C$13/12,$O158,240,Calculator!$C$11,0,),0),"") | T158: =IF(Calculator!$C$12=20,Q158-R158,"")
H159: 155 | I159: =IF(Calculator!$C$12=12,"",Calculator!$C$14) | J159: =M158 | K159: =IF(Calculator!$C$12=15,ROUNDUP(-PPMT(Calculator!$C$13/12,$H159,180,Calculator!$C$11,0,),0),"") | L159: =IF(Calculator!$C$12=15,ROUNDUP(-IPMT(Calculator!$C$13/12,$H159,180,Calculator!$C$11,0,),0),"") | M159: =IF(Calculator!$C$12=15,J159-K159,"") | O159: 155 | P159: =IF(Calculator!$C$12=20,Calculator!$C$14,"") | Q159: =T158 | R159: =IF(Calculator!$C$12=20,ROUNDUP(-PPMT(Calculator!$C$13/12,$O159,240,Calculator!$C$11,0,),0),"") | S159: =IF(Calculator!$C$12=20,ROUNDUP(-IPMT(Calculator!$C$13/12,$O159,240,Calculator!$C$11,0,),0),"") | T159: =IF(Calculator!$C$12=20,Q159-R159,"")
H160: 156 | I160: =IF(Calculator!$C$12=12,"",Calculator!$C$14) | J160: =M159 | K160: =IF(Calculator!$C$12=15,ROUNDUP(-PPMT(Calculator!$C$13/12,$H160,180,Calculator!$C$11,0,),0),"") | L160: =IF(Calculator!$C$12=15,ROUNDUP(-IPMT(Calculator!$C$13/12,$H160,180,Calculator!$C$11,0,),0),"") | M160: =IF(Calculator!$C$12=15,J160-K160,"") | O160: 156 | P160: =IF(Calculator!$C$12=20,Calculator!$C$14,"") | Q160: =T159 | R160: =IF(Calculator!$C$12=20,ROUNDUP(-PPMT(Calculator!$C$13/12,$O160,240,Calculator!$C$11,0,),0),"") | S160: =IF(Calculator!$C$12=20,ROUNDUP(-IPMT(Calculator!$C$13/12,$O160,240,Calculator!$C$11,0,),0),"") | T160: =IF(Calculator!$C$12=20,Q160-R160,"")
... H183: 179 | I183: =IF(Calculator!$C$12=12,"",Calculator!$C$14) | J183: =M182 | K183: =IF(Calculator!$C$12=15,ROUNDUP(-PPMT(Calculator!$C$13/12,$H183,180,Calculator!$C$11,0,),0),"") | L183: =IF(Calculator!$C$12=15,ROUNDUP(-IPMT(Calculator!$C$13/12,$H183,180,Calculator!$C$11,0,),0),"") | M183: =IF(Calculator!$C$12=15,J183-K183,"") | O183: 179 | P183: =IF(Calculator!$C$12=20,Calculator!$C$14,"") | Q183: =T182 | R183: =IF(Calculator!$C$12=20,ROUNDUP(-PPMT(Calculator!$C$13/12,$O183,240,Calculator!$C$11,0,),0),"") | S183: =IF(Calculator!$C$12=20,ROUNDUP(-IPMT(Calculator!$C$13/12,$O183,240,Calculator!$C$11,0,),0),"") | T183: =IF(Calculator!$C$12=20,Q183-R183,"")
H184: 180 | I184: =K184+L184 -> #VALUE! | J184: =M183 | K184: =J184 | L184: =M183*Calculator!$C$13/12 -> #VALUE! | M184: =IF(Calculator!$C$12=15,J184-K184,"") | O184: 180 | P184: =IF(Calculator!$C$12=20,Calculator!$C$14,"") | Q184: =T183 | R184: =IF(Calculator!$C$12=20,ROUNDUP(-PPMT(Calculator!$C$13/12,$O184,240,Calculator!$C$11,0,),0),"") | S184: =IF(Calculator!$C$12=20,ROUNDUP(-IPMT(Calculator!$C$13/12,$O184,240,Calculator!$C$11,0,),0),"") | T184: =IF(Calculator!$C$12=20,Q184-R184,"")
O185: 181 | P185: =IF(Calculator!$C$12=20,Calculator!$C$14,"") | Q185: =T184 | R185: =IF(Calculator!$C$12=20,ROUNDUP(-PPMT(Calculator!$C$13/12,$O185,240,Calculator!$C$11,0,),0),"") | S185: =IF(Calculator!$C$12=20,ROUNDUP(-IPMT(Calculator!$C$13/12,$O185,240,Calculator!$C$11,0,),0),"") | T185: =IF(Calculator!$C$12=20,Q185-R185,"")
O186: 182 | P186: =IF(Calculator!$C$12=20,Calculator!$C$14,"") | Q186: =T185 | R186: =IF(Calculator!$C$12=20,ROUNDUP(-PPMT(Calculator!$C$13/12,$O186,240,Calculator!$C$11,0,),0),"") | S186: =IF(Calculator!$C$12=20,ROUNDUP(-IPMT(Calculator!$C$13/12,$O186,240,Calculator!$C$11,0,),0),"") | T186: =IF(Calculator!$C$12=20,Q186-R186,"")
O187: 183 | P187: =IF(Calculator!$C$12=20,Calculator!$C$14,"") | Q187: =T186 | R187: =IF(Calculator!$C$12=20,ROUNDUP(-PPMT(Calculator!$C$13/12,$O187,240,Calculator!$C$11,0,),0),"") | S187: =IF(Calculator!$C$12=20,ROUNDUP(-IPMT(Calculator!$C$13/12,$O187,240,Calculator!$C$11,0,),0),"") | T187: =IF(Calculator!$C$12=20,Q187-R187,"")
O188: 184 | P188: =IF(Calculator!$C$12=20,Calculator!$C$14,"") | Q188: =T187 | R188: =IF(Calculator!$C$12=20,ROUNDUP(-PPMT(Calculator!$C$13/12,$O188,240,Calculator!$C$11,0,),0),"") | S188: =IF(Calculator!$C$12=20,ROUNDUP(-IPMT(Calculator!$C$13/12,$O188,240,Calculator!$C$11,0,),0),"") | T188: =IF(Calculator!$C$12=20,Q188-R188,"")
O189: 185 | P189: =IF(Calculator!$C$12=20,Calculator!$C$14,"") | Q189: =T188 | R189: =IF(Calculator!$C$12=20,ROUNDUP(-PPMT(Calculator!$C$13/12,$O189,240,Calculator!$C$11,0,),0),"") | S189: =IF(Calculator!$C$12=20,ROUNDUP(-IPMT(Calculator!$C$13/12,$O189,240,Calculator!$C$11,0,),0),"") | T189: =IF(Calculator!$C$12=20,Q189-R189,"")
O190: 186 | P190: =IF(Calculator!$C$12=20,Calculator!$C$14,"") | Q190: =T189 | R190: =IF(Calculator!$C$12=20,ROUNDUP(-PPMT(Calculator!$C$13/12,$O190,240,Calculator!$C$11,0,),0),"") | S190: =IF(Calculator!$C$12=20,ROUNDUP(-IPMT(Calculator!$C$13/12,$O190,240,Calculator!$C$11,0,),0),"") | T190: =IF(Calculator!$C$12=20,Q190-R190,"")
O191: 187 | P191: =IF(Calculator!$C$12=20,Calculator!$C$14,"") | Q191: =T190 | R191: =IF(Calculator!$C$12=20,ROUNDUP(-PPMT(Calculator!$C$13/12,$O191,240,Calculator!$C$11,0,),0),"") | S191: =IF(Calculator!$C$12=20,ROUNDUP(-IPMT(Calculator!$C$13/12,$O191,240,Calculator!$C$11,0,),0),"") | T191: =IF(Calculator!$C$12=20,Q191-R191,"")
O192: 188 | P192: =IF(Calculator!$C$12=20,Calculator!$C$14,"") | Q192: =T191 | R192: =IF(Calculator!$C$12=20,ROUNDUP(-PPMT(Calculator!$C$13/12,$O192,240,Calculator!$C$11,0,),0),"") | S192: =IF(Calculator!$C$12=20,ROUNDUP(-IPMT(Calculator!$C$13/12,$O192,240,Calculator!$C$11,0,),0),"") | T192: =IF(Calculator!$C$12=20,Q192-R192,"")
O193: 189 | P193: =IF(Calculator!$C$12=20,Calculator!$C$14,"") | Q193: =T192 | R193: =IF(Calculator!$C$12=20,ROUNDUP(-PPMT(Calculator!$C$13/12,$O193,240,Calculator!$C$11,0,),0),"") | S193: =IF(Calculator!$C$12=20,ROUNDUP(-IPMT(Calculator!$C$13/12,$O193,240,Calculator!$C$11,0,),0),"") | T193: =IF(Calculator!$C$12=20,Q193-R193,"")
...
