Workbook
Name Program: GrantProgram[Program]
Name Program: GrantProgram[Program]
Name State: Table4[State / Protectorate]
Name State: Table4[State / Protectorate]

Sheet  Budget Worksheet-REQUIRED
A1: Western SARE Budget Worksheet for Award Year 2025 - REQUIRED
C2: Please fill out all fields in yellow
B3: Project PI Name: | G3: PI State/Protectorate: | J3: dropdown | K3: TOTAL COSTS: | L3: =L180 -> 0
B4: PI Institution/Organization:
B5: Project Start Date: | D5: (mm/dd/yyyy)
B6: Project End Date: | D6: (mm/dd/yyyy)
A7: PLEASE READ ALL NOTES BELOW and REVIEW the BUDGET CATEGORIES and GUIDANCE tab before beginning.
A8: Using this Budget Worksheet to submit the detailed budget is REQUIRED! Previous versions of this worksheet will not be accepted. The budget categories below match MSU & Western SARE's approved budget template. Please note the following: max project length and allowable expenses vary by grant program; see the Call for Proposals (CFP) for the specific grant program to which you are applying for details. Matching contributions are not required; please do not include.
A9: DIRECTIONS: Complete the Budget Worksheet below. Yellow fields are for input. Green fields are locked and will auto-calculate, rounding to the nearest dollar value. Because elements of this worksheet are locked to maintain formula integrity, additional lines cannot be inserted; please enter additional budget detail, by category and year, on the worksheet tab labeled "Budget Cont." (see Tabs at bottom). Subtotals from the "Budget Cont." worksheet will auto-fill on this worksheet. Tip: the columns with an asterisk (*) indicate that values must be entered below in order for the subtotals to auto-calculate, or that values must be directly entered. Finally, a detailed budget justification is also required. A proper budget justification describes how proposed costs will be used to support the project. Please follow the directions in the CFP or SARE Grant Management System for submitting a budget justification; following the same order of budget categories below is appreciated and will facilitate budget review.
A10: Please refer to the Budget Categories and Guidance tab at bottom for information and guidance on which costs to include in each budget category.
A12: Sections A & B - Salary & Benefits:
B13: Salaries (Name): | C13: Role/Title | D13: Estimated Effort (FTE or hours) | E13: Annual Base Salary | F13: (A) Amount Salary Requested* | G13: Fringe Benefits Rate | H13: (B) Amount Benefits Requested* | I13: Year 1 Amount Requested | J13: Year 2 Amount Requested | K13: Year 3 Amount Requested | L13: SUMMARY
B14: Key Personnel (includes PI, Co-PIs, Collaborators) | I14: Auto-Calculates
A15: Year 1 | I15: =F15+H15 -> 0
A16: Year 1 | I16: =F16+H16 -> 0
A17: Year 1 | I17: =F17+H17 -> 0
A18: Year 1 | I18: =F18+H18 -> 0
A19: Year 1 | I19: =F19+H19 -> 0 | J19: Auto-Calculates
A20: Year 2 | J20: =F20+H20 -> 0
A21: Year 2 | J21: =F21+H21 -> 0
A22: Year 2 | J22: =F22+H22 -> 0
A23: Year 2 | J23: =F23+H23 -> 0
A24: Year 2 | J24: =F24+H24 -> 0 | K24: Auto-Calculates
A25: Year 3 | K25: =F25+H25 -> 0
A26: Year 3 | K26: =F26+H26 -> 0
A27: Year 3 | K27: =F27+H27 -> 0
A28: Year 3 | K28: =F28+H28 -> 0
A29: Year 3 | K29: =F29+H29 -> 0
B30: Other Personnel (includes support staff, technicians, student wages, etc. ) | I30: Auto-Calculates
A31: Year 1 | I31: =F31+H31 -> 0
A32: Year 1 | I32: =F32+H32 -> 0
A33: Year 1 | I33: =F33+H33 -> 0
A34: Year 1 | I34: =F34+H34 -> 0
A35: Year 1 | I35: =F35+H35 -> 0 | J35: Auto-Calculates
A36: Year 2 | J36: =F36+H36 -> 0
A37: Year 2 | J37: =F37+H37 -> 0
A38: Year 2 | J38: =F38+H38 -> 0
A39: Year 2 | J39: =F39+H39 -> 0
A40: Year 2 | J40: =F40+H40 -> 0 | K40: Auto-Calculates
A41: Year 3 | K41: =F41+H41 -> 0
...

Sheet Budget Cont.
A1: Western SARE Budget Worksheet - Additional Budget Details
A2: Please use this worksheet if additional space/lines are needed by project year. Subtotals from this worksheet will auto-fill on the main budget worksheet tab.
A4: Sections A & B - Salary & Benefits:
B5: Salaries (Name): | C5: Role/Title | D5: Estimated Effort (FTE or hours) | E5: Annual Base Salary | F5: (A) Amount Salary Requested* | G5: Fringe Benefits Rate | H5: (B) Amount Benefits Requested* | I5: Year 1 Amount Requested | J5: Year 2 Amount Requested | K5: Year 3 Amount Requested | L5: SUMMARY
B6: Key Personnel (includes PI, Co-PIs, Collaborators) | I6: Auto-Calculates
A7: Year 1 | I7: =F7+H7 -> 0
A8: Year 1 | I8: =F8+H8 -> 0
A9: Year 1 | I9: =F9+H9 -> 0
A10: Year 1 | I10: =F10+H10 -> 0
A11: Year 1 | I11: =F11+H11 -> 0 | J11: Auto-Calculates
A12: Year 2 | J12: =F12+H12 -> 0
A13: Year 2 | J13: =F13+H13 -> 0
A14: Year 2 | J14: =F14+H14 -> 0
A15: Year 2 | J15: =F15+H15 -> 0
A16: Year 2 | J16: =F16+H16 -> 0 | K16: Auto-Calculates
A17: Year 3 | K17: =F17+H17 -> 0
A18: Year 3 | K18: =F18+H18 -> 0
A19: Year 3 | K19: =F19+H19 -> 0
A20: Year 3 | K20: =F20+H20 -> 0
A21: Year 3 | K21: =F21+H21 -> 0
B22: Other Personnel (includes support staff, technicians, student wages, etc. ) | I22: Auto-Calculates
A23: Year 1 | I23: =F23+H23 -> 0
A24: Year 1 | I24: =F24+H24 -> 0
A25: Year 1 | I25: =F25+H25 -> 0
A26: Year 1 | I26: =F26+H26 -> 0
A27: Year 1 | I27: =F27+H27 -> 0 | J27: Auto-Calculates
A28: Year 2 | J28: =F28+H28 -> 0
A29: Year 2 | J29: =F29+H29 -> 0
A30: Year 2 | J30: =F30+H30 -> 0
A31: Year 2 | J31: =F31+H31 -> 0
A32: Year 2 | J32: =F32+H32 -> 0 | K32: Auto-Calculates
A33: Year 3 | K33: =F33+H33 -> 0
A34: Year 3 | K34: =F34+H34 -> 0
A35: Year 3 | K35: =F35+H35 -> 0
A36: Year 3 | K36: =F36+H36 -> 0
A37: Year 3 | K37: =F37+H37 -> 0 | L37: Auto-Calculates
D38: Subtotals: | E38: Salaries (A): | F38: =SUM(F7:F21)+SUM(F23:F37) -> 0 | G38: Benefits (B): | H38: =SUM(H7:H21)+SUM(H23:H37) -> 0 | K38: Personnel Total | L38: =SUM(I7:I11)+SUM(J12:J16)+SUM(K17:K21)+SUM(I23:I27)+SUM(J28:J32)+SUM(K33:K37) -> 0
A40: Section C - Lower-tier Subaward Costs:
B41: Lower-tier Subrecipient PI | C41: Lower-tier Subrecipient Institution/Organization Name | I41: Enter Amount(s)*
A42: Year 1
...

Sheet Budget Categories and Guidance
A1: Western SARE Approved Budget Categories, Guidance and Unallowable Costs
A3: Please use the following information to determine the budget categories for your project expenses. The information that follows also will be useful in determining general allowability of costs for the SARE program. Please also see the specific Call for Proposals for the program you are applying to for specific information regarding allowablity of costs.
A4: (A) Salary | B4: Personnel costs. Employees of the applicant organization/insitution who will be paid directly from the grant for work on the proposed project. Identify each person who will work on the project (or indicate TBD if person will be hired), their role and estimated FTE. Either the annual base salary or hourly rate MUST be provided for each to be paid from the project budget (if unknown, estimate salary or rate). Include the total salary support requested.
A6: (B) Benefits | B6: Includes associated benefits (fringe and health, if applicable) paid on behalf of organization’s employees paid directly from this award.
A8: (C) Lower-tier Subawards | B8: The applicant institution may issue lower-tier subaward(s) in order to pay project collaborators who are not at their institution and/or to support costs associated with the lower-tier subrecipient’s portion of the proposed project. Lower-tier Subrecipients are named institutions and shall have a Principal Investigator. Characteristics whose presence supports the classification of an entity as a subrecipient are when the entity receiving funds under the award: • Determines who is eligible to receive Federal funds; • Has its performance measured in relation to whether objectives of a Federal program were met; • Has responsibility for programmatic decision making; • Is responsible for adherence to applicable Federal program requirements specified in the Federal award; and • In accordance with its agreement, uses the Federal funds to carry out a program for a public purpose specified in authorizing statute, as opposed to providing goods or services for the benefit of the pass-through entity
B9: For each proposed Lower-tier Subaward, list the name of the institution / organization AND name of lower-tier subaward Project Leader / collaborator (PI). In the budget justification, also provide a brief description of the plan of work and total funds requested, by year. Note: for EACH proposed Lower-tier Subaward, a separate Western SARE Budget Worksheet for Lower-tier Subawards and corresponding budget justification must be submitted with the proposal. Important Note: if using the de minimis IDC rate (see section J, below), the amount of each Lower-tier Subaward that exceeds $25,000 must be excluded from the IDC base.
A11: (D) Contracted Services | B11: Includes paying an organization/business or individual for goods, services and/or consulting; fee-for-service work; honoraria. Characteristics of Contractors include: • Provides the goods or services within normal business operations; • Provides similar goods or services to many different purchasers; • Operates in a competitive environment; • Provides goods or services that are ancillary to the operation of the research project, and • Is not subject to monitoring or reporting requirements of the prime award. Characteristics of Consultants (must not exceed customary rate of pay) include: • A company or an individual who is clearly a bona fide consultant (expert advisor) who pursues this line of business for him/herself. • Are paid for their time at a daily or hourly fixed rate. • A consultant is considered a “work for hire” thus all intellectual property and copyrightable information is assigned to Montana State University. This budget category also includes paying individuals for participating in activities and/or providing services related to your project, e.g., collecting and providing samples, etc. Other examples include: computer services, professional service fees, honoraria, speaker fees, testing/analysis services
A13: (E) Supplies | B13: Includes basic supplies and materials needed to carry out the project. Examples include: agricultural supplies (temporary fencing, seeds, plants, fertilizer), field and lab supplies, minor equipment and tools (individual items that cost less than $5,000), paper/envelopes, in-house photocopying of materials for workshops/meetings, software, books, shipping materials. Any shipping costs associated with the purchase of supplies/materials should be included as supply costs. The purchase of food/refreshments for meetings/field days (must be justified as necessary to maintain meeting continuity) is also considered a supply cost. Please keep the following in mind: • Supplies must be project-specific and be able to be tracked as being used for the project. • Individual items that cost $500 or more must be listed separately. • Include “Minor Equipment” and/or leveraged capital equipment purchases as supply costs.
B14: Special Note about Capital Equipment Purchase: Purchase of capital equipment (defined as a single, autonomous piece of equipment that costs $5,000 or more and has a useful life of more than one year) is generally not allowed under the SARE program. Capital equipment purchase of $5,000 or more may be leveraged by non-Western SARE funds; thus, up to $4,999 of the proposed budget may be allocated towards capital equipment purchase. This expense must be well-justified. Purchasing components of equipment that individually cost under $5,000 in an attempt to circumvent the $5,000 cap is not allowed. Minor equipment that costs less than $5,000 is allowed. Please include minor equipment and/or leveraged capital equipment purchases in the Supplies budget category.
A16: (F) Communication | B16: Includes postage and mailing expenses (including shipping samples for analysis), printed materials (flyers, brochures, posters). This category also includes expenses for publishing articles in a scientific journals or other types of field/program publications, or for commercial photocopying (note: in-house photocopying falls under supplies)
A18: (G) Travel | B18: Travel must be directly related to the project and includes: mileage reimbursement, airfare, lodging, meal per diem; car rentals, taxi, bus, shuttle expenses and parking; conference fees and registrations. [Please note, travel per diems and mileage need to correlate with your organization's approved rates. If no rate is available, please use the Federal Government rate listed on the U.S. General Services Administration website. Additionally, lodging costs/reimbursements for ALL travel must be limited to the Federal Government rate listed on the U.S. General Services Administration website:
B19: https://www.gsa.gov/travel/plan-book/per-diem-rates
B20: Note on International Travel Requests: Typically, international travel is NOT allowed on any Western SARE grants. An applicant may request funds to support international travel at the proposal stage. Such requests must be well justified and detail how it is critical to fulfilling project objectives and why the work cannot be completed domestically. If the proposal is selected for funding, it is NOT an indication that the international travel has been approved. The proposed budget will be reviewed and international travel requests will be carefully considered. The PI will be informed at award time as to whether the international travel has been approved and/or whether additional infomation is needed.
A22: (H) Rent | B22: Includes rental fees for equipment, land, facilities (e.g., meeting rooms, lab space) and user fees. Note: capital equipment rental costs are capped at $4,999 over the life of the project.
A24: (I) Participant/ Trainee Support | B24: A participant is defined as a non-employee (of the applicant’s institution) who is the recipient, not the provider, of a service or training opportunity as part of a workshop, conference, seminar, symposium or other short-term instructional or information sharing activity to be funded by this award. Participant support may be paid to non-employees to help offset the cost of travel/lodging and meeting/training fees and/or as a stipend for participation in a training. Participant/trainee support should NOT be used: to reimburse or pay employees of the applicant’s institution; to pay research subjects/participants (unallowable expense under the SARE program); for honoraria/speaker fees (contracted services expense); or, if travel expenses for a non-employee will be directly reimbursed by the institution (travel expense). The applicant’s institution must maintain back-up documentation for all participant support costs in accordance with their institution’s policy. Note: if funds are budgeted for participant support at the time of award and the PI later wishes to reduce or remove this budget line, prior-approval from Western SARE via a Project Modification re-budget request is required to re-allocate those funds to a different budget category.
A26: (J) Indirect Costs Recovery (IDCs) ONLY ONE APPLIES | B26: (1) Organizations that have a Federally Negotiated Indirect Cost Rate (NICRA): IDCs are calculated at a rate of 10% of Total Direct Costs (TDC). This is the maximum indirect cost recovery (IDC cap) allowed under the SARE program per USDA-NIFA. The 10% TDC IDC cap should be consistently applied to both the primary applicant and proposed lower-tier subrecipients, if applicable; therefore, include the total costs of any/all proposed lower-tier subawards in the IDC recovery base.
A28: OR | B28: (2) Non-Federal entities that do NOT have a federally negotiated rate for indirect costs, and never had one previously, or that previously had a NICRA but it is no longer in effect: May claim 10% of modified total direct costs (MTDC) as de minimis to cover overhead. MTDC includes all direct salaries and wages, applicable fringe benefits, materials and supplies, services, travel, and up to the first $25,000 of each lower-tier subaward (regardless of the period of performance of the subawards under the award). MTDC excludes participant support costs and the portion of each lower-tier subaward budget in excess of $25,000.
A30: OR | B30: (3) If none of the above AND the PI's institution/organization does not want to claim the de minimis, IDC recovery is not required.
A32: UNALLOWABLE COSTS - All Western SARE Grant Programs
A33: Per NIFA's Federal Assistance Policy Guide published April 2021, below is a list of unallowable costs. Budgets that include any of the following will not be approved and/or the PI will be asked to re-budget. Please note: this list is not exhaustive; budgets will be reviewed for allowability/allocability of all proposed costs in relation to the proposed project activities.
A34: Link to NIFA Federal Assistance Policy Guide [https://www.nifa.usda.gov/nifa-federal-assistance-policy-guide]
A35: Cost | B35: NIFA Description
A36: Entertainment | B36: Costs of entertainment, including amusement, diversion, and social activities and any associated costs
A37: Equipment (Capital) | B37: See (E) Supplies above for more details
A38: Fixed Equipment & Acquisition or Construction of Real Property | B38: The purchase or installation of fixed equipment in such spaces; or for the planning, repair, rehabilitation, acquisition, or construction of a building or facility.
A39: Incentives | B39: Cash or cash value items (i.e., gift cards) provided to individuals to incentivize behavior.
A40: Lobbying | B40: Any actions designed to influence the obtaining of grants or influence or give special consideration to action on an award or regulatory matter.
A41: Meals/Food | B41: Business meals may not be charged as project costs when individuals decide to go to breakfast, lunch, or dinner together when no need exists for continuity of a meeting. Such activity is considered to be an entertainment cost. However, meals that are part of the costs of meetings and conferences, the primary purpose of which is the dissemination of technical information, are allowable as are costs of transportation, rental of facilities, speakers’ fees, and other items incidental to such meetings or conferences. Note: Meals consumed while in official travel status do not fall in this category. They are considered to be per diem expenses and should be reimbursed in accordance with the organization’s established travel policies subject to statutory limitations.
A42: Memberships (Lobbying) | B42: Costs of membership in organization whose primary purpose is lobbying.
A43: Promotional Items | B43: Items purchased to give-away: conference giveaways; t-shirts; bags, pens, pencils, mugs, bottles, etc.
A44: Renovation or Refurbishment of Research Spaces | B44: Renovation or refurbishment of laboratories or other research spaces
A45: T-shirts, Clothes | B45: For staff or participants, or so personnel can be identified as working on the project, or as give-aways/promotion of the program.
A47: Additionally, Western SARE funds may NOT be used for the following purposes:
A48: ~ Student tuition remission and fees
A49: ~ The purchase and distribution of gift cards/certificates for any purpose
A50: ~ Starting or expanding a farm or farm operation
A51: ~ Major renovations/permanent improvement to a farm, ranch, research or office space, such as construction or remodeling a building
A52: ~ Major repairs to existing equipment and infrastructure
A53: ~ Testing of commercial products
A54: ~ Furniture/furnishings of any type for any purpose.
...

Sheet Data
A1: Program
A2: Research and Education
A3: Professional + Producer
A4: Farmer / Rancher
A5: Graduate Student
A6: Competitive PDP
A7: State Implementation
A8: State Enhancement
A9: Research to Grassroots
A15: State / Protectorate
A16: Alaska
A17: American Samoa
... A33: Other
